<?xml version="1.0" ?>
<!-- =================================================================================== -->
<!-- |    This document was autogenerated by xacro from msd_tunnel_sensor.xacro        | -->
<!-- |    EDITING THIS FILE BY HAND IS NOT RECOMMENDED                                 | -->
<!-- =================================================================================== -->
<robot name="msd_tunnel_dtw">
  <material name="gray">
    <color rgba="0.3 0.3 0.3 1.0"/>
  </material>
  <material name="red">
    <color rgba="1.0 0.0 0.0 1.0"/>
  </material>
  <link name="base_link"/>
  <joint name="body_joint" type="fixed">
    <parent link="base_link"/>
    <child link="body_link"/>
    <origin rpy="0 0 0" xyz="0 0 0"/>
  </joint>
  <link name="body_link">
    <inertial>
      <origin rpy="0 0 0" xyz="0 0 0"/>
      <mass value="18.28"/>
      <inertia ixx="0.001" ixy="0.0" ixz="0.0" iyy="0.001" iyz="0.0" izz="0.001"/>
    </inertial>
    <visual>
      <origin rpy="0 0 0" xyz="0 0 0"/>
      <geometry>
        <mesh filename="package://msd_simulator/model/meshes/msd_tunnel/body.dae"/>
      </geometry>
      <material name="gray"/>
    </visual>
    <collision>
      <origin rpy="0 0 0" xyz="0 0 0.250"/>
      <geometry>
        <box size="0.800 0.480 0.400"/>
      </geometry>
    </collision>
  </link>
  <gazebo reference="body_link">
    <material>Gazebo/Gray</material>
  </gazebo>
  <joint name="left_wheel_joint" type="continuous">
    <origin rpy="0 0 0" xyz="-0.2575 0.300 0.1105"/>
    <parent link="base_link"/>
    <child link="left_wheel_link"/>
    <axis xyz="0 1 0"/>
  </joint>
  <transmission name="left_wheel_trans" type="SimpleTransmission">
    <type>transmission_interface/SimpleTransmission</type>
    <actuator name="left_wheel_motor">
      <mechanicalReduction>1</mechanicalReduction>
    </actuator>
    <joint name="left_wheel_joint">
      <hardwareInterface>hardware_interface/VelocityJointInterface</hardwareInterface>
    </joint>
  </transmission>
  <link name="left_wheel_link">
    <inertial>
      <mass value="3.5"/>
      <inertia ixx="0.0001" ixy="0.0" ixz="0.0" iyy="0.0001" iyz="0.0" izz="0.0001"/>
    </inertial>
    <visual>
      <geometry>
        <mesh filename="package://msd_simulator/model/meshes/msd_tunnel/drive_wheel.dae"/>
      </geometry>
      <material name="red"/>
    </visual>
    <collision>
      <origin rpy="1.57 0 0" xyz="0 0 0"/>
      <geometry>
        <cylinder length="0.076" radius="0.1105"/>
      </geometry>
    </collision>
  </link>
  <gazebo reference="left_wheel_link">
    <material>Gazebo/Red</material>
    <mu1 value="1.0"/>
    <mu2 value="1.0"/>
    <kp value="10000000"/>
    <kd value="10"/>
  </gazebo>
  <joint name="right_wheel_joint" type="continuous">
    <origin rpy="0 0 0" xyz="-0.2575 -0.300 0.1105"/>
    <parent link="base_link"/>
    <child link="right_wheel_link"/>
    <axis xyz="0 1 0"/>
  </joint>
  <transmission name="right_wheel_trans" type="SimpleTransmission">
    <type>transmission_interface/SimpleTransmission</type>
    <actuator name="right_wheel_motor">
      <mechanicalReduction>1</mechanicalReduction>
    </actuator>
    <joint name="right_wheel_joint">
      <hardwareInterface>hardware_interface/VelocityJointInterface</hardwareInterface>
    </joint>
  </transmission>
  <link name="right_wheel_link">
    <inertial>
      <mass value="3.5"/>
      <inertia ixx="0.0001" ixy="0.0" ixz="0.0" iyy="0.0001" iyz="0.0" izz="0.0001"/>
    </inertial>
    <visual>
      <geometry>
        <mesh filename="package://msd_simulator/model/meshes/msd_tunnel/drive_wheel.dae"/>
      </geometry>
      <material name="red"/>
    </visual>
    <collision>
      <origin rpy="1.57 0 0" xyz="0 0 0"/>
      <geometry>
        <cylinder length="0.076" radius="0.1105"/>
      </geometry>
    </collision>
  </link>
  <gazebo reference="right_wheel_link">
    <material>Gazebo/Red</material>
    <mu1 value="1.0"/>
    <mu2 value="1.0"/>
    <kp value="10000000"/>
    <kd value="10"/>
  </gazebo>
  <!-- -0.2575 -300 0.053 -->
  <joint name="left_front_joint" type="fixed">
    <parent link="base_link"/>
    <child link="left_front_link"/>
    <origin rpy="0 0 0" xyz="0.287 0.295 0.055"/>
  </joint>
  <link name="left_front_link">
    <inertial>
      <mass value="1.1"/>
      <inertia ixx="0.0001" ixy="0.0" ixz="0.0" iyy="0.0001" iyz="0.0" izz="0.0001"/>
    </inertial>
    <visual>
      <origin rpy="0 0 0" xyz="0 0 0"/>
      <geometry>
        <mesh filename="package://msd_simulator/model/meshes/msd_tunnel/roller.dae"/>
      </geometry>
    </visual>
    <collision>
      <origin rpy="1.57 0 0" xyz="0 0 0"/>
      <geometry>
        <cylinder length="0.076" radius="0.055"/>
      </geometry>
    </collision>
  </link>
  <gazebo reference="left_front_link">
    <material>Gazebo/Gray</material>
    <mu1 value="0.1"/>
    <mu2 value="0.1"/>
    <kp value="10000000"/>
    <kd value="10"/>
  </gazebo>
  <joint name="left_center_joint" type="fixed">
    <parent link="base_link"/>
    <child link="left_center_link"/>
    <origin rpy="0 0 0" xyz="0.0175 0.295 0.055"/>
  </joint>
  <link name="left_center_link">
    <inertial>
      <mass value="1.1"/>
      <inertia ixx="0.0001" ixy="0.0" ixz="0.0" iyy="0.0001" iyz="0.0" izz="0.0001"/>
    </inertial>
    <visual>
      <origin rpy="0 0 0" xyz="0 0 0"/>
      <geometry>
        <mesh filename="package://msd_simulator/model/meshes/msd_tunnel/roller.dae"/>
      </geometry>
    </visual>
    <collision>
      <origin rpy="1.57 0 0" xyz="0 0 0"/>
      <geometry>
        <cylinder length="0.076" radius="0.055"/>
      </geometry>
    </collision>
  </link>
  <gazebo reference="left_center_link">
    <material>Gazebo/Gray</material>
    <mu1 value="0.1"/>
    <mu2 value="0.1"/>
    <kp value="10000000"/>
    <kd value="10"/>
  </gazebo>
  <joint name="right_front_joint" type="fixed">
    <parent link="base_link"/>
    <child link="right_front_link"/>
    <origin rpy="0 0 0" xyz="0.287 -0.295 0.055"/>
  </joint>
  <link name="right_front_link">
    <inertial>
      <mass value="1.1"/>
      <inertia ixx="0.0001" ixy="0.0" ixz="0.0" iyy="0.0001" iyz="0.0" izz="0.0001"/>
    </inertial>
    <visual>
      <origin rpy="0 0 0" xyz="0 0 0"/>
      <geometry>
        <mesh filename="package://msd_simulator/model/meshes/msd_tunnel/roller.dae"/>
      </geometry>
    </visual>
    <collision>
      <origin rpy="1.57 0 0" xyz="0 0 0"/>
      <geometry>
        <cylinder length="0.076" radius="0.055"/>
      </geometry>
    </collision>
  </link>
  <gazebo reference="right_front_link">
    <material>Gazebo/Gray</material>
    <mu1 value="0.1"/>
    <mu2 value="0.1"/>
    <kp value="10000000"/>
    <kd value="10"/>
  </gazebo>
  <joint name="right_center_joint" type="fixed">
    <parent link="base_link"/>
    <child link="right_center_link"/>
    <origin rpy="0 0 0" xyz="0.0175 -0.295 0.055"/>
  </joint>
  <link name="right_center_link">
    <inertial>
      <mass value="1.1"/>
      <inertia ixx="0.0001" ixy="0.0" ixz="0.0" iyy="0.0001" iyz="0.0" izz="0.0001"/>
    </inertial>
    <visual>
      <origin rpy="0 0 0" xyz="0 0 0"/>
      <geometry>
        <mesh filename="package://msd_simulator/model/meshes/msd_tunnel/roller.dae"/>
      </geometry>
    </visual>
    <collision>
      <origin rpy="1.57 0 0" xyz="0 0 0"/>
      <geometry>
        <cylinder length="0.076" radius="0.055"/>
      </geometry>
    </collision>
  </link>
  <gazebo reference="right_center_link">
    <material>Gazebo/Gray</material>
    <mu1 value="0.1"/>
    <mu2 value="0.1"/>
    <kp value="10000000"/>
    <kd value="10"/>
  </gazebo>
  <joint name="rplidar_s1_joint" type="fixed">
    <parent link="base_link"/>
    <child link="rplidar_s1_link"/>
    <origin rpy="0 0 0" xyz="0.4385 0 0.2121"/>
  </joint>
  <link name="rplidar_s1_link">
    <visual>
      <origin rpy="0 0 0" xyz="0 0 0"/>
      <geometry>
        <cylinder length="0.06" radius="0.02"/>
      </geometry>
      <material name="red"/>
    </visual>
    <collision>
      <origin rpy="0 0 0" xyz="0 0 0"/>
      <geometry>
        <cylinder length="0.06" radius="0.02"/>
      </geometry>
    </collision>
  </link>
  <gazebo reference="rplidar_s1_link">
    <material>Gazebo/Red</material>
    <sensor name="rplidar_s1" type="ray">
      <pose>0 0 0 0 0 0</pose>
      <visualize>false</visualize>
      <update_rate>10</update_rate>
      <ray>
        <scan>
          <horizontal>
            <samples>400</samples>
            <resolution>1</resolution>
            <min_angle>-1.5707963267948966</min_angle>
            <max_angle>1.5707963267948966</max_angle>
          </horizontal>
        </scan>
        <range>
          <min>0.10</min>
          <max>20.0</max>
          <resolution>0.01</resolution>
        </range>
        <noise>
          <type>gaussian</type>
          <mean>0.0</mean>
          <stddev>0.01</stddev>
        </noise>
      </ray>
      <plugin filename="libgazebo_ros_laser.so" name="gazebo_ros_lidar_controller">
        <topicName>/rplidar_s1_link/scan</topicName>
        <frameName>rplidar_s1_link</frameName>
      </plugin>
    </sensor>
  </gazebo>
  <gazebo>
    <plugin filename="libgazebo_ros_control.so" name="gazebo_ros_control">
      <robotNamespace>/msd_tunnel_dtw</robotNamespace>
      <robotSimType>gazebo_ros_control/DefaultRobotHWSim</robotSimType>
      <legacyModeNS>true</legacyModeNS>
    </plugin>
  </gazebo>
</robot>

