<?xml version="1.0" ?>
<!-- =================================================================================== -->
<!-- |    This document was autogenerated by xacro from msd_tunnel_dtw.xacro           | -->
<!-- |    EDITING THIS FILE BY HAND IS NOT RECOMMENDED                                 | -->
<!-- =================================================================================== -->
<robot name="msd_tunnel_dtw">
  <material name="gray">
    <color rgba="0.5 0.5 0.5 1.0"/>
  </material>
  <material name="red">
    <color rgba="1.0 0.0 0.0 1.0"/>
  </material>
  <link name="base_link"/>
  <joint name="body_joint" type="fixed">
    <parent link="base_link"/>
    <child link="body_link"/>
    <origin rpy="0 0 0" xyz="0 0 0"/>
  </joint>
  <link name="body_link">
    <inertial>
      <origin rpy="0 0 0" xyz="0 0 0"/>
      <mass value="182.8"/>
      <inertia ixx="0.001" ixy="0.0" ixz="0.0" iyy="0.001" iyz="0.0" izz="0.001"/>
    </inertial>
    <visual>
      <origin rpy="0 0 0" xyz="0 0 0"/>
      <geometry>
        <mesh filename="package://msd_simulator/model/meshes/msd_tunnel/body.dae"/>
      </geometry>
    </visual>
    <collision>
      <origin rpy="0 0 0" xyz="0 0 0"/>
      <geometry>
        <box size="1.0 0.700 0.250"/>
      </geometry>
    </collision>
  </link>
  <gazebo reference="body_link">
    <material>Gazebo/Gray</material>
  </gazebo>
  <joint name="left_wheel_joint" type="continuous">
    <origin rpy="0 0 0" xyz="0 0.1 0.05"/>
    <parent link="base_link"/>
    <child link="left_wheel_link"/>
    <axis xyz="0 1 0"/>
  </joint>
  <transmission name="left_wheel_trans" type="SimpleTransmission">
    <type>transmission_interface/SimpleTransmission</type>
    <actuator name="left_wheel_motor">
      <mechanicalReduction>1</mechanicalReduction>
    </actuator>
    <joint name="left_wheel_joint">
      <hardwareInterface>hardware_interface/VelocityJointInterface</hardwareInterface>
    </joint>
  </transmission>
  <link name="left_wheel_link">
    <inertial>
      <origin rpy="0 0 0" xyz="0 0 0"/>
      <mass value="3.5"/>
      <inertia ixx="0.0001" ixy="0.0" ixz="0.0" iyy="0.0001" iyz="0.0" izz="0.0001"/>
    </inertial>
    <visual>
      <geometry>
        <mesh filename="package://msd_simulator/model/meshes/msd_tunnel/drive_wheel.dae"/>
      </geometry>
      <material name="red"/>
    </visual>
    <collision>
      <geometry>
        <cylinder length="0.076" radius="0.1105"/>
      </geometry>
    </collision>
  </link>
  <gazebo reference="left_wheel_link">
    <material>Gazebo/Red</material>
    <mu1 value="0.9"/>
    <mu2 value="0.9"/>
    <kp value="50000"/>
    <kd value="10"/>
  </gazebo>
  <joint name="right_wheel_joint" type="continuous">
    <origin rpy="0 0 0" xyz="0 -0.1 0.05"/>
    <parent link="base_link"/>
    <child link="right_wheel_link"/>
    <axis xyz="0 1 0"/>
  </joint>
  <transmission name="right_wheel_trans" type="SimpleTransmission">
    <type>transmission_interface/SimpleTransmission</type>
    <actuator name="right_wheel_motor">
      <mechanicalReduction>1</mechanicalReduction>
    </actuator>
    <joint name="right_wheel_joint">
      <hardwareInterface>hardware_interface/VelocityJointInterface</hardwareInterface>
    </joint>
  </transmission>
  <link name="right_wheel_link">
    <inertial>
      <origin rpy="0 0 0" xyz="0 0 0"/>
      <mass value="3.5"/>
      <inertia ixx="0.0001" ixy="0.0" ixz="0.0" iyy="0.0001" iyz="0.0" izz="0.0001"/>
    </inertial>
    <visual>
      <geometry>
        <mesh filename="package://msd_simulator/model/meshes/msd_tunnel/drive_wheel.dae"/>
      </geometry>
      <material name="red"/>
    </visual>
    <collision>
      <geometry>
        <cylinder length="0.076" radius="0.1105"/>
      </geometry>
    </collision>
  </link>
  <gazebo reference="right_wheel_link">
    <material>Gazebo/Red</material>
    <mu1 value="0.9"/>
    <mu2 value="0.9"/>
    <kp value="50000"/>
    <kd value="10"/>
  </gazebo>
  <joint name="left_front_joint" type="fixed">
    <parent link="base_link"/>
    <child link="left_front_link"/>
    <origin rpy="0 0 0" xyz="0.287 0.295 0.110"/>
  </joint>
  <link name="left_front_link">
    <visual>
      <origin rpy="0 0 0" xyz="0 0 0"/>
      <geometry>
        <mesh filename="package://msd_simulator/model/meshes/msd_tunnel/roller.dae"/>
      </geometry>
    </visual>
    <collision>
      <origin rpy="0 0 0" xyz="0 0 0"/>
      <geometry>
        <cylinder length="0.076" radius="0.055"/>
      </geometry>
      <material name="gray"/>
    </collision>
  </link>
  <gazebo reference="left_front_link">
    <material>Gazebo/Gray</material>
    <mu1 value="0.1"/>
    <mu2 value="0.1"/>
  </gazebo>
  <joint name="left_center_joint" type="fixed">
    <parent link="base_link"/>
    <child link="left_center_link"/>
    <origin rpy="0 0 0" xyz="0.0175 0.295 0.110"/>
  </joint>
  <link name="left_center_link">
    <visual>
      <origin rpy="0 0 0" xyz="0 0 0"/>
      <geometry>
        <mesh filename="package://msd_simulator/model/meshes/msd_tunnel/roller.dae"/>
      </geometry>
    </visual>
    <collision>
      <origin rpy="0 0 0" xyz="0 0 0"/>
      <geometry>
        <cylinder length="0.076" radius="0.055"/>
      </geometry>
      <material name="gray"/>
    </collision>
  </link>
  <gazebo reference="left_center_link">
    <material>Gazebo/Gray</material>
    <mu1 value="0.1"/>
    <mu2 value="0.1"/>
  </gazebo>
  <joint name="right_front_joint" type="fixed">
    <parent link="base_link"/>
    <child link="right_front_link"/>
    <origin rpy="0 0 0" xyz="0.287 -0.295 0.110"/>
  </joint>
  <link name="right_front_link">
    <visual>
      <origin rpy="0 0 0" xyz="0 0 0"/>
      <geometry>
        <mesh filename="package://msd_simulator/model/meshes/msd_tunnel/roller.dae"/>
      </geometry>
    </visual>
    <collision>
      <origin rpy="0 0 0" xyz="0 0 0"/>
      <geometry>
        <cylinder length="0.076" radius="0.055"/>
      </geometry>
      <material name="gray"/>
    </collision>
  </link>
  <gazebo reference="right_front_link">
    <material>Gazebo/Gray</material>
    <mu1 value="0.1"/>
    <mu2 value="0.1"/>
  </gazebo>
  <joint name="right_center_joint" type="fixed">
    <parent link="base_link"/>
    <child link="right_center_link"/>
    <origin rpy="0 0 0" xyz="0.0175 -0.295 0.110"/>
  </joint>
  <link name="right_center_link">
    <visual>
      <origin rpy="0 0 0" xyz="0 0 0"/>
      <geometry>
        <mesh filename="package://msd_simulator/model/meshes/msd_tunnel/roller.dae"/>
      </geometry>
    </visual>
    <collision>
      <origin rpy="0 0 0" xyz="0 0 0"/>
      <geometry>
        <cylinder length="0.076" radius="0.055"/>
      </geometry>
      <material name="gray"/>
    </collision>
  </link>
  <gazebo reference="right_center_link">
    <material>Gazebo/Gray</material>
    <mu1 value="0.1"/>
    <mu2 value="0.1"/>
  </gazebo>
  <gazebo>
    <plugin filename="libgazebo_ros_control.so" name="gazebo_ros_control">
      <robotNamespace>/msd_tunnel_dtw</robotNamespace>
      <robotSimType>gazebo_ros_control/DefaultRobotHWSim</robotSimType>
      <legacyModeNS>true</legacyModeNS>
    </plugin>
  </gazebo>
</robot>

